<mujoco model="mobile_inverted_pendulum">
  <compiler angle="degree" coordinate="local" inertiafromgeom="true"/>
  <option gravity="0 0 -9.81" timestep="0.002" integrator="implicit"/>
  
  <default>
    <joint damping="0.1" />
    <geom friction="1.0 0.1 0.1" />
  </default>
  
  <asset>
    <texture name="grid" type="2d" builtin="checker" width="512" height="512" 
             rgb1="0.2 0.3 0.4" rgb2="0.1 0.15 0.2"/>
    <material name="grid" texture="grid" texrepeat="1 1" texuniform="true" reflectance="0.2"/>
  </asset>
  
  <worldbody>
    <!-- Ground plane -->
    <geom name="ground" type="plane" pos="0 0 0" size="10 10 0.1" 
          material="grid" condim="3"/>
    
    <light directional="true" pos="0 0 3" dir="0 0 -1"/>
  
    <!-- Mobile robot chassis (elevated by wheel radius) -->
    <body name="chassis" pos="0 0 0.1">
      <freejoint name="chassis_free"/>
      <geom name="chassis_geom" type="box" size="0.2 0.15 0.05" 
            density="500" rgba="0.3 0.3 0.8 1"/>
      <geom name="chassis_top" type="box" size="0.15 0.12 0.02" 
            pos="0 0 0.07" density="200" rgba="0.4 0.4 0.9 1"/>
      
      <!-- IMU sensor site on chassis -->
      <site name="imu_site" pos="0 0 0.05" size="0.01"/>
      
      <!-- Left wheel (upright, touching ground) -->
      <body name="wheel_left" pos="0 0.17 -0.05" euler="90 0 0">
        <joint name="left_wheel_joint" type="hinge" axis="0 0 1" 
               damping="0.1" frictionloss="0.01"/>
        <geom name="wheel_left_geom" type="cylinder" size="0.05 0.025" 
              density="300" rgba="0.1 0.1 0.1 1" 
              friction="1.5 0.01 0.01"/>
      </body>
  
      <!-- Right wheel (upright, touching ground) -->
      <body name="wheel_right" pos="0 -0.17 -0.05" euler="90 0 0">
        <joint name="right_wheel_joint" type="hinge" axis="0 0 1" 
               damping="0.1" frictionloss="0.01"/>
        <geom name="wheel_right_geom" type="cylinder" size="0.05 0.025" 
              density="300" rgba="0.1 0.1 0.1 1" 
              friction="1.5 0.01 0.01"/>
      </body>
      
      <!-- Caster wheel (front support, touching ground) -->
      <body name="caster" pos="0.15 0 -0.08">
        <geom name="caster_geom" type="sphere" size="0.02" 
              density="100" rgba="0.2 0.2 0.2 1" 
              friction="0.1 0.01 0.01"/>
      </body>
      
      <!-- Inverted pendulum mount point -->
      <body name="pendulum_base" pos="0 0 0.09">
        
        <!-- Pendulum rod -->
        <body name="pendulum_rod" pos="0 0 0">
          <joint name="pendulum_hinge" type="hinge" axis="0 1 0" 
                 damping="0.01" frictionloss="0.001" 
                 range="-180 180" limited="false"/>
          
          <!-- Rod visualization -->
          <geom name="pendulum_rod_geom" type="capsule" 
                fromto="0 0 0 0 0 0.5" size="0.015" 
                density="100" rgba="0.8 0.2 0.2 1"/>
          
          <!-- Top mass (the ball to balance) -->
          <body name="pendulum_mass" pos="0 0 0.5">
            <geom name="top_mass_geom" type="sphere" size="0.08" 
                  density="800" rgba="0.9 0.1 0.1 1"/>
          </body>
          
        </body>
      </body>
    </body>
  </worldbody>
  
  <actuator>
    <!-- Velocity actuators for differential drive -->
    <velocity name="left_motor" joint="left_wheel_joint" 
              kv="10" gear="1" ctrllimited="true" ctrlrange="-50 50"/>
    <velocity name="right_motor" joint="right_wheel_joint" 
              kv="10" gear="1" ctrllimited="true" ctrlrange="-50 50"/>
  </actuator>
  
  <sensor>
    <!-- Pendulum angle -->
    <jointpos name="pendulum_angle" joint="pendulum_hinge"/>
    <jointvel name="pendulum_velocity" joint="pendulum_hinge"/>
    
    <!-- Wheel positions and velocities -->
    <jointpos name="left_wheel_pos" joint="left_wheel_joint"/>
    <jointvel name="left_wheel_vel" joint="left_wheel_joint"/>
    <jointpos name="right_wheel_pos" joint="right_wheel_joint"/>
    <jointvel name="right_wheel_vel" joint="right_wheel_joint"/>
    
    <!-- Chassis state -->
    <framepos name="chassis_position" objtype="body" objname="chassis"/>
    <framelinvel name="chassis_velocity" objtype="body" objname="chassis"/>
    <framequat name="chassis_orientation" objtype="body" objname="chassis"/>
    <gyro name="chassis_gyro" site="imu_site"/>
    <accelerometer name="chassis_accel" site="imu_site"/>
  </sensor>
</mujoco>